Workbook
Name Slicer_Month: #N/A
Name Slicer_Week: #N/A
Name Slicer_Year: #N/A

Sheet Social_Media_Platform_Analysis
H2: Social Media Platform Analysis
X4: Visualize the engagement by ad spent across platform | AM4: Advise whether to focus on 1-2 core platforms or multiplatforms
I5: Comparing the growth rate of followers per Platform( Growth rate = (New followers - Unfollowers)/previous week followers) | W5: Platform | X5: Date | Y5: Engagement(Likes+Shares+Comments) | Z5: Month | AA5: Week | AB5: Year | AC5: ad spent | AM5: Average of Engagement(Likes+Shares+Comments) | AN5: Year
D6: Highest Engagement Platform | W6: Facebook | X6: 45444 | Y6: =SUM([1]!Posts[[#This Row],[Likes]],[1]!Posts[[#This Row],[Shares]],[1]!Posts[[#This Row],[Comments]]) -> 2949 | Z6: =MONTH(X6) -> 6 | AA6: =INT((DAY(X6)-1)/7)+1 -> 1 | AB6: =YEAR(X6) -> 2024 | AC6: {=_xlfn.XLOOKUP(1, ('[1]Engagement Summary(Task1)'!$J$2:$J$201=Social_Media_Platform_Analysis!$AA6)*('[1]Engagement Summary(Task1)'!$I$2:$I$201=Social_Media_Platform_Analysis!$Z6)*('[1]Engagement Summary(Task1)'!$H$2:$H$201=Social_Media_Platform_Analysis!$AB6)*('[1]Engagement Summary(Task1)'!$B$2:$B$201=Social_Media_Platform_Analysis!$W6),'[1]Engagement Summary(Task1)'!$G$2:$G$201)} -> 9566 | AM6: Platform | AN6: 2024 | AO6: 2025 | AP6: Grand Total
B7: {=_xlfn.TAKE('[1]Engagement Summary(Task1)'!B:B,201,1)} -> Platform | C7: {=_xlfn.TAKE('[1]Engagement Summary(Task1)'!F1:F201,201,1)} -> Engagement_Rate | D7: Platform | E7: Average of Engagement_Rate | G7: {=_xlfn.TAKE('[1]Engagement Summary(Task1)'!B1:B201,201,1)} -> Platform | H7: {=_xlfn.TAKE('[1]Engagement Summary(Task1)'!E:E,201,1)} -> Total_Followers | I7: {=_xlfn.TAKE('[1]Engagement Summary(Task1)'!H:H,201,1)} -> Year | J7: {=_xlfn.TAKE('[1]Engagement Summary(Task1)'!I:I,201,1)} -> Month | K7: {=_xlfn.TAKE('[1]Engagement Summary(Task1)'!J:J,201,1)} -> Week | L7: {=_xlfn.TAKE('[1]Engagement Summary(Task1)'!K:K,201,1)} -> Netgrowth | M7: {=_xlfn.TAKE('[1]Engagement Summary(Task1)'!L:L,201,1)} -> Growth Rate | N7: Row Labels | O7: Average of Growth Rate | W7: Facebook | X7: 45445 | Y7: =SUM([1]!Posts[[#This Row],[Likes]],[1]!Posts[[#This Row],[Shares]],[1]!Posts[[#This Row],[Comments]]) -> 2905 | Z7: =MONTH(X7) -> 6 | AA7: =INT((DAY(X7)-1)/7)+1 -> 1 | AB7: =YEAR(X7) -> 2024 | AC7: {=_xlfn.XLOOKUP(1, ('[1]Engagement Summary(Task1)'!$J$2:$J$201=Social_Media_Platform_Analysis!$AA7)*('[1]Engagement Summary(Task1)'!$I$2:$I$201=Social_Media_Platform_Analysis!$Z7)*('[1]Engagement Summary(Task1)'!$H$2:$H$201=Social_Media_Platform_Analysis!$AB7)*('[1]Engagement Summary(Task1)'!$B$2:$B$201=Social_Media_Platform_Analysis!$W7),'[1]Engagement Summary(Task1)'!$G$2:$G$201)} -> 9566 | AM7: Facebook | AN7: 3327.2373 | AO7: 2487.4118 | AP7: 3020.2043
B8: Facebook | C8: 0.0498 | D8: Facebook | E8: 0.056486 | G8: Facebook | H8: 42654 | I8: 2024 | J8: 6 | K8: 1 | L8: 1002 | M8: 1 | N8: Facebook | O8: 1.0858217 | W8: Facebook | X8: 45454 | Y8: =SUM([1]!Posts[[#This Row],[Likes]],[1]!Posts[[#This Row],[Shares]],[1]!Posts[[#This Row],[Comments]]) -> 4668 | Z8: =MONTH(X8) -> 6 | AA8: =INT((DAY(X8)-1)/7)+1 -> 2 | AB8: =YEAR(X8) -> 2024 | AC8: {=_xlfn.XLOOKUP(1, ('[1]Engagement Summary(Task1)'!$J$2:$J$201=Social_Media_Platform_Analysis!$AA8)*('[1]Engagement Summary(Task1)'!$I$2:$I$201=Social_Media_Platform_Analysis!$Z8)*('[1]Engagement Summary(Task1)'!$H$2:$H$201=Social_Media_Platform_Analysis!$AB8)*('[1]Engagement Summary(Task1)'!$B$2:$B$201=Social_Media_Platform_Analysis!$W8),'[1]Engagement Summary(Task1)'!$G$2:$G$201)} -> 7924 | AE8: Platform | AF8: Average of Engagement | AG8: Average of ad spent | AM8: Instagram | AN8: 3659.1525 | AO8: 3756.5172 | AP8: 3691.2386
B9: Facebook | C9: 0.0237 | D9: Instagram | E9: 0.057156 | G9: Facebook | H9: 316555 | I9: 2024 | J9: 6 | K9: 2 | L9: 1283 | M9: 1.2804391 | N9: 2024 | O9: 1.1414989 | W9: Facebook | X9: 45454 | Y9: =SUM([1]!Posts[[#This Row],[Likes]],[1]!Posts[[#This Row],[Shares]],[1]!Posts[[#This Row],[Comments]]) -> 4668 | Z9: =MONTH(X9) -> 6 | AA9: =INT((DAY(X9)-1)/7)+1 -> 2 | AB9: =YEAR(X9) -> 2024 | AC9: {=_xlfn.XLOOKUP(1, ('[1]Engagement Summary(Task1)'!$J$2:$J$201=Social_Media_Platform_Analysis!$AA9)*('[1]Engagement Summary(Task1)'!$I$2:$I$201=Social_Media_Platform_Analysis!$Z9)*('[1]Engagement Summary(Task1)'!$H$2:$H$201=Social_Media_Platform_Analysis!$AB9)*('[1]Engagement Summary(Task1)'!$B$2:$B$201=Social_Media_Platform_Analysis!$W9),'[1]Engagement Summary(Task1)'!$G$2:$G$201)} -> 7924 | AE9: Facebook | AF9: 3020.2043 | AG9: 27501.667 | AM9: Twitter | AN9: 3472.2222 | AO9: 3310.8158 | AP9: 3405.5543
B10: Facebook | C10: 0.0811 | D10: Twitter | E10: 0.056558 | G10: Facebook | H10: 169496 | I10: 2024 | J10: 6 | K10: 3 | L10: 1382 | M10: 1.0771629 | N10: 2025 | O10: 0.97446717 | W10: Facebook | X10: 45456 | Y10: =SUM([1]!Posts[[#This Row],[Likes]],[1]!Posts[[#This Row],[Shares]],[1]!Posts[[#This Row],[Comments]]) -> 4230 | Z10: =MONTH(X10) -> 6 | AA10: =INT((DAY(X10)-1)/7)+1 -> 2 | AB10: =YEAR(X10) -> 2024 | AC10: {=_xlfn.XLOOKUP(1, ('[1]Engagement Summary(Task1)'!$J$2:$J$201=Social_Media_Platform_Analysis!$AA10)*('[1]Engagement Summary(Task1)'!$I$2:$I$201=Social_Media_Platform_Analysis!$Z10)*('[1]Engagement Summary(Task1)'!$H$2:$H$201=Social_Media_Platform_Analysis!$AB10)*('[1]Engagement Summary(Task1)'!$B$2:$B$201=Social_Media_Platform_Analysis!$W10),'[1]Engagement Summary(Task1)'!$G$2:$G$201)} -> 7924 | AE10: 2024 | AF10: 3327.2373 | AG10: 24532.576 | AM10: YouTube | AN10: 3931.1463 | AO10: 3526.16 | AP10: 3777.7424
B11: Facebook | C11: 0.0912 | D11: YouTube | E11: 0.055588 | G11: Facebook | H11: 26295 | I11: 2024 | J11: 6 | K11: 4 | L11: 1670 | M11: 1.2083936 | N11: Instagram | O11: 1.0046728 | W11: Facebook | X11: 45460 | Y11: =SUM([1]!Posts[[#This Row],[Likes]],[1]!Posts[[#This Row],[Shares]],[1]!Posts[[#This Row],[Comments]]) -> 4340 | Z11: =MONTH(X11) -> 6 | AA11: =INT((DAY(X11)-1)/7)+1 -> 3 | AB11: =YEAR(X11) -> 2024 | AC11: {=_xlfn.XLOOKUP(1, ('[1]Engagement Summary(Task1)'!$J$2:$J$201=Social_Media_Platform_Analysis!$AA11)*('[1]Engagement Summary(Task1)'!$I$2:$I$201=Social_Media_Platform_Analysis!$Z11)*('[1]Engagement Summary(Task1)'!$H$2:$H$201=Social_Media_Platform_Analysis!$AB11)*('[1]Engagement Summary(Task1)'!$B$2:$B$201=Social_Media_Platform_Analysis!$W11),'[1]Engagement Summary(Task1)'!$G$2:$G$201)} -> 46670 | AE11: 2025 | AF11: 2487.4118 | AG11: 32653.912 | AM11: Grand Total | AN11: 3572.1784 | AO11: 3233.9365 | AP11: 3446.4602
B12: Facebook | C12: 0.0448 | D12: Grand Total | E12: 0.056447 | G12: Facebook | H12: 220020 | I12: 2024 | J12: 7 | K12: 1 | L12: 64 | M12: 0.038323353 | N12: 2024 | O12: 0.98135795 | W12: Facebook | X12: 45462 | Y12: =SUM([1]!Posts[[#This Row],[Likes]],[1]!Posts[[#This Row],[Shares]],[1]!Posts[[#This Row],[Comments]]) -> 4469 | Z12: =MONTH(X12) -> 6 | AA12: =INT((DAY(X12)-1)/7)+1 -> 3 | AB12: =YEAR(X12) -> 2024 | AC12: {=_xlfn.XLOOKUP(1, ('[1]Engagement Summary(Task1)'!$J$2:$J$201=Social_Media_Platform_Analysis!$AA12)*('[1]Engagement Summary(Task1)'!$I$2:$I$201=Social_Media_Platform_Analysis!$Z12)*('[1]Engagement Summary(Task1)'!$H$2:$H$201=Social_Media_Platform_Analysis!$AB12)*('[1]Engagement Summary(Task1)'!$B$2:$B$201=Social_Media_Platform_Analysis!$W12),'[1]Engagement Summary(Task1)'!$G$2:$G$201)} -> 46670 | AE12: Instagram | AF12: 3691.2386 | AG12: 25164.932
B13: Facebook | C13: 0.0191 | G13: Facebook | H13: 251694 | I13: 2024 | J13: 7 | K13: 2 | L13: 309 | M13: 4.828125 | N13: 2025 | O13: 1.0513025 | W13: Facebook | X13: 45463 | Y13: =SUM([1]!Posts[[#This Row],[Likes]],[1]!Posts[[#This Row],[Shares]],[1]!Posts[[#This Row],[Comments]]) -> 4996 | Z13: =MONTH(X13) -> 6 | AA13: =INT((DAY(X13)-1)/7)+1 -> 3 | AB13: =YEAR(X13) -> 2024 | AC13: {=_xlfn.XLOOKUP(1, ('[1]Engagement Summary(Task1)'!$J$2:$J$201=Social_Media_Platform_Analysis!$AA13)*('[1]Engagement Summary(Task1)'!$I$2:$I$201=Social_Media_Platform_Analysis!$Z13)*('[1]Engagement Summary(Task1)'!$H$2:$H$201=Social_Media_Platform_Analysis!$AB13)*('[1]Engagement Summary(Task1)'!$B$2:$B$201=Social_Media_Platform_Analysis!$W13),'[1]Engagement Summary(Task1)'!$G$2:$G$201)} -> 46670 | AE13: 2024 | AF13: 3659.1525 | AG13: 25947.034 | AM13: Engagement year wise
B14: Facebook | C14: 0.0644 | G14: Facebook | H14: 334626 | I14: 2024 | J14: 7 | K14: 3 | L14: -164 | M14: -0.53074434 | N14: Twitter | O14: 1.8043865 | W14: Facebook | X14: 45465 | Y14: =SUM([1]!Posts[[#This Row],[Likes]],[1]!Posts[[#This Row],[Shares]],[1]!Posts[[#This Row],[Comments]]) -> 5190 | Z14: =MONTH(X14) -> 6 | AA14: =INT((DAY(X14)-1)/7)+1 -> 4 | AB14: =YEAR(X14) -> 2024 | AC14: {=_xlfn.XLOOKUP(1, ('[1]Engagement Summary(Task1)'!$J$2:$J$201=Social_Media_Platform_Analysis!$AA14)*('[1]Engagement Summary(Task1)'!$I$2:$I$201=Social_Media_Platform_Analysis!$Z14)*('[1]Engagement Summary(Task1)'!$H$2:$H$201=Social_Media_Platform_Analysis!$AB14)*('[1]Engagement Summary(Task1)'!$B$2:$B$201=Social_Media_Platform_Analysis!$W14),'[1]Engagement Summary(Task1)'!$G$2:$G$201)} -> 30635 | AE14: 2025 | AF14: 3756.5172 | AG14: 23573.759
B15: Facebook | C15: 0.0786 | G15: Facebook | H15: 295032 | I15: 2024 | J15: 7 | K15: 4 | L15: 961 | M15: -5.8597561 | N15: 2024 | O15: 2.2638365 | W15: Facebook | X15: 45465 | Y15: =SUM([1]!Posts[[#This Row],[Likes]],[1]!Posts[[#This Row],[Shares]],[1]!Posts[[#This Row],[Comments]]) -> 2903 | Z15: =MONTH(X15) -> 6 | AA15: =INT((DAY(X15)-1)/7)+1 -> 4 | AB15: =YEAR(X15) -> 2024 | AC15: {=_xlfn.XLOOKUP(1, ('[1]Engagement Summary(Task1)'!$J$2:$J$201=Social_Media_Platform_Analysis!$AA15)*('[1]Engagement Summary(Task1)'!$I$2:$I$201=Social_Media_Platform_Analysis!$Z15)*('[1]Engagement Summary(Task1)'!$H$2:$H$201=Social_Media_Platform_Analysis!$AB15)*('[1]Engagement Summary(Task1)'!$B$2:$B$201=Social_Media_Platform_Analysis!$W15),'[1]Engagement Summary(Task1)'!$G$2:$G$201)} -> 30635 | AE15: Twitter | AF15: 3405.5543 | AG15: 20814.761
B16: Facebook | C16: 0.0773 | G16: Facebook | H16: 435034 | I16: 2024 | J16: 7 | K16: 5 | L16: -318 | M16: -0.33090531 | N16: 2025 | O16: 0.88548635 | W16: Facebook | X16: 45480 | Y16: =SUM([1]!Posts[[#This Row],[Likes]],[1]!Posts[[#This Row],[Shares]],[1]!Posts[[#This Row],[Comments]]) -> 3009 | Z16: =MONTH(X16) -> 7 | AA16: =INT((DAY(X16)-1)/7)+1 -> 1 | AB16: =YEAR(X16) -> 2024 | AC16: {=_xlfn.XLOOKUP(1, ('[1]Engagement Summary(Task1)'!$J$2:$J$201=Social_Media_Platform_Analysis!$AA16)*('[1]Engagement Summary(Task1)'!$I$2:$I$201=Social_Media_Platform_Analysis!$Z16)*('[1]Engagement Summary(Task1)'!$H$2:$H$201=Social_Media_Platform_Analysis!$AB16)*('[1]Engagement Summary(Task1)'!$B$2:$B$201=Social_Media_Platform_Analysis!$W16),'[1]Engagement Summary(Task1)'!$G$2:$G$201)} -> 42307 | AE16: 2024 | AF16: 3472.2222 | AG16: 21786.87
B17: Facebook | C17: 0.0611 | G17: Facebook | H17: 125034 | I17: 2024 | J17: 8 | K17: 1 | L17: -197 | M17: 0.61949686 | N17: YouTube | O17: 0.47538121 | W17: Facebook | X17: 45480 | Y17: =SUM([1]!Posts[[#This Row],[Likes]],[1]!Posts[[#This Row],[Shares]],[1]!Posts[[#This Row],[Comments]]) -> 1688 | Z17: =MONTH(X17) -> 7 | AA17: =INT((DAY(X17)-1)/7)+1 -> 1 | AB17: =YEAR(X17) -> 2024 | AC17: {=_xlfn.XLOOKUP(1, ('[1]Engagement Summary(Task1)'!$J$2:$J$201=Social_Media_Platform_Analysis!$AA17)*('[1]Engagement Summary(Task1)'!$I$2:$I$201=Social_Media_Platform_Analysis!$Z17)*('[1]Engagement Summary(Task1)'!$H$2:$H$201=Social_Media_Platform_Analysis!$AB17)*('[1]Engagement Summary(Task1)'!$B$2:$B$201=Social_Media_Platform_Analysis!$W17),'[1]Engagement Summary(Task1)'!$G$2:$G$201)} -> 42307 | AE17: 2025 | AF17: 3310.8158 | AG17: 19433.342
B18: Facebook | C18: 0.0601 | D18: Formulas Used | G18: Facebook | H18: 307612 | I18: 2024 | J18: 8 | K18: 2 | L18: 1334 | M18: -6.7715736 | N18: 2024 | O18: 0.47149391 | W18: Facebook | X18: 45488 | Y18: =SUM([1]!Posts[[#This Row],[Likes]],[1]!Posts[[#This Row],[Shares]],[1]!Posts[[#This Row],[Comments]]) -> 4928 | Z18: =MONTH(X18) -> 7 | AA18: =INT((DAY(X18)-1)/7)+1 -> 3 | AB18: =YEAR(X18) -> 2024 | AC18: {=_xlfn.XLOOKUP(1, ('[1]Engagement Summary(Task1)'!$J$2:$J$201=Social_Media_Platform_Analysis!$AA18)*('[1]Engagement Summary(Task1)'!$I$2:$I$201=Social_Media_Platform_Analysis!$Z18)*('[1]Engagement Summary(Task1)'!$H$2:$H$201=Social_Media_Platform_Analysis!$AB18)*('[1]Engagement Summary(Task1)'!$B$2:$B$201=Social_Media_Platform_Analysis!$W18),'[1]Engagement Summary(Task1)'!$G$2:$G$201)} -> 43420 | AE18: YouTube | AF18: 3777.7424 | AG18: 28013.045
B19: Facebook | C19: 0.0884 | D19: To calculate net growth | E19: New followers - Unfollowers | G19: Facebook | H19: 183924 | I19: 2024 | J19: 8 | K19: 3 | L19: 1058 | M19: 0.79310345 | N19: 2025 | O19: 0.48315582 | W19: Facebook | X19: 45488 | Y19: =SUM([1]!Posts[[#This Row],[Likes]],[1]!Posts[[#This Row],[Shares]],[1]!Posts[[#This Row],[Comments]]) -> 4620 | Z19: =MONTH(X19) -> 7 | AA19: =INT((DAY(X19)-1)/7)+1 -> 3 | AB19: =YEAR(X19) -> 2024 | AC19: {=_xlfn.XLOOKUP(1, ('[1]Engagement Summary(Task1)'!$J$2:$J$201=Social_Media_Platform_Analysis!$AA19)*('[1]Engagement Summary(Task1)'!$I$2:$I$201=Social_Media_Platform_Analysis!$Z19)*('[1]Engagement Summary(Task1)'!$H$2:$H$201=Social_Media_Platform_Analysis!$AB19)*('[1]Engagement Summary(Task1)'!$B$2:$B$201=Social_Media_Platform_Analysis!$W19),'[1]Engagement Summary(Task1)'!$G$2:$G$201)} -> 43420 | AE19: 2024 | AF19: 3931.1463 | AG19: 27745.829
B20: Facebook | C20: 0.0904 | G20: Facebook | H20: 379380 | I20: 2024 | J20: 8 | K20: 4 | L20: 37 | M20: 0.034971645 | N20: Grand Total | O20: 1.0925655 | W20: Facebook | X20: 45488 | Y20: =SUM([1]!Posts[[#This Row],[Likes]],[1]!Posts[[#This Row],[Shares]],[1]!Posts[[#This Row],[Comments]]) -> 4189 | Z20: =MONTH(X20) -> 7 | AA20: =INT((DAY(X20)-1)/7)+1 -> 3 | AB20: =YEAR(X20) -> 2024 | AC20: {=_xlfn.XLOOKUP(1, ('[1]Engagement Summary(Task1)'!$J$2:$J$201=Social_Media_Platform_Analysis!$AA20)*('[1]Engagement Summary(Task1)'!$I$2:$I$201=Social_Media_Platform_Analysis!$Z20)*('[1]Engagement Summary(Task1)'!$H$2:$H$201=Social_Media_Platform_Analysis!$AB20)*('[1]Engagement Summary(Task1)'!$B$2:$B$201=Social_Media_Platform_Analysis!$W20),'[1]Engagement Summary(Task1)'!$G$2:$G$201)} -> 43420 | AE20: 2025 | AF20: 3526.16 | AG20: 28451.28
B21: Facebook | C21: 0.0641 | G21: Facebook | H21: 496982 | I21: 2024 | J21: 9 | K21: 1 | L21: 1045 | M21: 28.243243 | W21: Facebook | X21: 45488 | Y21: =SUM([1]!Posts[[#This Row],[Likes]],[1]!Posts[[#This Row],[Shares]],[1]!Posts[[#This Row],[Comments]]) -> 5022 | Z21: =MONTH(X21) -> 7 | AA21: =INT((DAY(X21)-1)/7)+1 -> 3 | AB21: =YEAR(X21) -> 2024 | AC21: {=_xlfn.XLOOKUP(1, ('[1]Engagement Summary(Task1)'!$J$2:$J$201=Social_Media_Platform_Analysis!$AA21)*('[1]Engagement Summary(Task1)'!$I$2:$I$201=Social_Media_Platform_Analysis!$Z21)*('[1]Engagement Summary(Task1)'!$H$2:$H$201=Social_Media_Platform_Analysis!$AB21)*('[1]Engagement Summary(Task1)'!$B$2:$B$201=Social_Media_Platform_Analysis!$W21),'[1]Engagement Summary(Task1)'!$G$2:$G$201)} -> 43420 | AE21: Grand Total | AF21: 3446.4602 | AG21: 25179.906
B22: Facebook | C22: 0.0176 | G22: Facebook | H22: 307524 | I22: 2024 | J22: 9 | K22: 2 | L22: 1428 | M22: 1.3665072 | W22: Facebook | X22: 45494 | Y22: =SUM([1]!Posts[[#This Row],[Likes]],[1]!Posts[[#This Row],[Shares]],[1]!Posts[[#This Row],[Comments]]) -> 3707 | Z22: =MONTH(X22) -> 7 | AA22: =INT((DAY(X22)-1)/7)+1 -> 3 | AB22: =YEAR(X22) -> 2024 | AC22: {=_xlfn.XLOOKUP(1, ('[1]Engagement Summary(Task1)'!$J$2:$J$201=Social_Media_Platform_Analysis!$AA22)*('[1]Engagement Summary(Task1)'!$I$2:$I$201=Social_Media_Platform_Analysis!$Z22)*('[1]Engagement Summary(Task1)'!$H$2:$H$201=Social_Media_Platform_Analysis!$AB22)*('[1]Engagement Summary(Task1)'!$B$2:$B$201=Social_Media_Platform_Analysis!$W22),'[1]Engagement Summary(Task1)'!$G$2:$G$201)} -> 43420
B23: Facebook | C23: 0.092 | D23: To calculate growth rate | E23: Netgraowth/ Previous week followers | G23: Facebook | H23: 474162 | I23: 2024 | J23: 9 | K23: 3 | L23: 98 | M23: 0.068627451 | W23: Facebook | X23: 45504 | Y23: =SUM([1]!Posts[[#This Row],[Likes]],[1]!Posts[[#This Row],[Shares]],[1]!Posts[[#This Row],[Comments]]) -> 1612 | Z23: =MONTH(X23) -> 7 | AA23: =INT((DAY(X23)-1)/7)+1 -> 5 | AB23: =YEAR(X23) -> 2024 | AC23: {=_xlfn.XLOOKUP(1, ('[1]Engagement Summary(Task1)'!$J$2:$J$201=Social_Media_Platform_Analysis!$AA23)*('[1]Engagement Summary(Task1)'!$I$2:$I$201=Social_Media_Platform_Analysis!$Z23)*('[1]Engagement Summary(Task1)'!$H$2:$H$201=Social_Media_Platform_Analysis!$AB23)*('[1]Engagement Summary(Task1)'!$B$2:$B$201=Social_Media_Platform_Analysis!$W23),'[1]Engagement Summary(Task1)'!$G$2:$G$201)} -> 4839
B24: Facebook | C24: 0.0736 | G24: Facebook | H24: 239753 | I24: 2024 | J24: 9 | K24: 4 | L24: -19 | M24: -0.19387755 | W24: Facebook | X24: 45504 | Y24: =SUM([1]!Posts[[#This Row],[Likes]],[1]!Posts[[#This Row],[Shares]],[1]!Posts[[#This Row],[Comments]]) -> 4915 | Z24: =MONTH(X24) -> 7 | AA24: =INT((DAY(X24)-1)/7)+1 -> 5 | AB24: =YEAR(X24) -> 2024 | AC24: {=_xlfn.XLOOKUP(1, ('[1]Engagement Summary(Task1)'!$J$2:$J$201=Social_Media_Platform_Analysis!$AA24)*('[1]Engagement Summary(Task1)'!$I$2:$I$201=Social_Media_Platform_Analysis!$Z24)*('[1]Engagement Summary(Task1)'!$H$2:$H$201=Social_Media_Platform_Analysis!$AB24)*('[1]Engagement Summary(Task1)'!$B$2:$B$201=Social_Media_Platform_Analysis!$W24),'[1]Engagement Summary(Task1)'!$G$2:$G$201)} -> 4839
B25: Facebook | C25: 0.0177 | G25: Facebook | H25: 453423 | I25: 2024 | J25: 9 | K25: 5 | L25: -179 | M25: 9.4210526 | W25: Facebook | X25: 45509 | Y25: =SUM([1]!Posts[[#This Row],[Likes]],[1]!Posts[[#This Row],[Shares]],[1]!Posts[[#This Row],[Comments]]) -> 5606 | Z25: =MONTH(X25) -> 8 | AA25: =INT((DAY(X25)-1)/7)+1 -> 1 | AB25: =YEAR(X25) -> 2024 | AC25: {=_xlfn.XLOOKUP(1, ('[1]Engagement Summary(Task1)'!$J$2:$J$201=Social_Media_Platform_Analysis!$AA25)*('[1]Engagement Summary(Task1)'!$I$2:$I$201=Social_Media_Platform_Analysis!$Z25)*('[1]Engagement Summary(Task1)'!$H$2:$H$201=Social_Media_Platform_Analysis!$AB25)*('[1]Engagement Summary(Task1)'!$B$2:$B$201=Social_Media_Platform_Analysis!$W25),'[1]Engagement Summary(Task1)'!$G$2:$G$201)} -> 26455
B26: Facebook | C26: 0.0175 | D26: To extact data from other sheet | E26: Used Take () | G26: Facebook | H26: 379363 | I26: 2024 | J26: 10 | K26: 1 | L26: 1662 | M26: -9.2849162 | W26: Facebook | X26: 45518 | Y26: =SUM([1]!Posts[[#This Row],[Likes]],[1]!Posts[[#This Row],[Shares]],[1]!Posts[[#This Row],[Comments]]) -> 2017 | Z26: =MONTH(X26) -> 8 | AA26: =INT((DAY(X26)-1)/7)+1 -> 2 | AB26: =YEAR(X26) -> 2024 | AC26: {=_xlfn.XLOOKUP(1, ('[1]Engagement Summary(Task1)'!$J$2:$J$201=Social_Media_Platform_Analysis!$AA26)*('[1]Engagement Summary(Task1)'!$I$2:$I$201=Social_Media_Platform_Analysis!$Z26)*('[1]Engagement Summary(Task1)'!$H$2:$H$201=Social_Media_Platform_Analysis!$AB26)*('[1]Engagement Summary(Task1)'!$B$2:$B$201=Social_Media_Platform_Analysis!$W26),'[1]Engagement Summary(Task1)'!$G$2:$G$201)} -> 37903
B27: Facebook | C27: 0.0388 | D27: To extract Month year and week from dates | E27: Used Month(), Year(), Week() | G27: Facebook | H27: 157599 | I27: 2024 | J27: 10 | K27: 2 | L27: 285 | M27: 0.17148014 | W27: Facebook | X27: 45521 | Y27: =SUM([1]!Posts[[#This Row],[Likes]],[1]!Posts[[#This Row],[Shares]],[1]!Posts[[#This Row],[Comments]]) -> 2469 | Z27: =MONTH(X27) -> 8 | AA27: =INT((DAY(X27)-1)/7)+1 -> 3 | AB27: =YEAR(X27) -> 2024 | AC27: {=_xlfn.XLOOKUP(1, ('[1]Engagement Summary(Task1)'!$J$2:$J$201=Social_Media_Platform_Analysis!$AA27)*('[1]Engagement Summary(Task1)'!$I$2:$I$201=Social_Media_Platform_Analysis!$Z27)*('[1]Engagement Summary(Task1)'!$H$2:$H$201=Social_Media_Platform_Analysis!$AB27)*('[1]Engagement Summary(Task1)'!$B$2:$B$201=Social_Media_Platform_Analysis!$W27),'[1]Engagement Summary(Task1)'!$G$2:$G$201)} -> 14203
B28: Facebook | C28: 0.0316 | G28: Facebook | H28: 23492 | I28: 2024 | J28: 10 | K28: 3 | L28: 439 | M28: 1.5403509 | W28: Facebook | X28: 45523 | Y28: =SUM([1]!Posts[[#This Row],[Likes]],[1]!Posts[[#This Row],[Shares]],[1]!Posts[[#This Row],[Comments]]) -> 2469 | Z28: =MONTH(X28) -> 8 | AA28: =INT((DAY(X28)-1)/7)+1 -> 3 | AB28: =YEAR(X28) -> 2024 | AC28: {=_xlfn.XLOOKUP(1, ('[1]Engagement Summary(Task1)'!$J$2:$J$201=Social_Media_Platform_Analysis!$AA28)*('[1]Engagement Summary(Task1)'!$I$2:$I$201=Social_Media_Platform_Analysis!$Z28)*('[1]Engagement Summary(Task1)'!$H$2:$H$201=Social_Media_Platform_Analysis!$AB28)*('[1]Engagement Summary(Task1)'!$B$2:$B$201=Social_Media_Platform_Analysis!$W28),'[1]Engagement Summary(Task1)'!$G$2:$G$201)} -> 14203
B29: Facebook | C29: 0.0446 | G29: Facebook | H29: 209987 | I29: 2024 | J29: 10 | K29: 4 | L29: 386 | M29: 0.87927107 | W29: Facebook | X29: 45523 | Y29: =SUM([1]!Posts[[#This Row],[Likes]],[1]!Posts[[#This Row],[Shares]],[1]!Posts[[#This Row],[Comments]]) -> 4853 | Z29: =MONTH(X29) -> 8 | AA29: =INT((DAY(X29)-1)/7)+1 -> 3 | AB29: =YEAR(X29) -> 2024 | AC29: {=_xlfn.XLOOKUP(1, ('[1]Engagement Summary(Task1)'!$J$2:$J$201=Social_Media_Platform_Analysis!$AA29)*('[1]Engagement Summary(Task1)'!$I$2:$I$201=Social_Media_Platform_Analysis!$Z29)*('[1]Engagement Summary(Task1)'!$H$2:$H$201=Social_Media_Platform_Analysis!$AB29)*('[1]Engagement Summary(Task1)'!$B$2:$B$201=Social_Media_Platform_Analysis!$W29),'[1]Engagement Summary(Task1)'!$G$2:$G$201)} -> 14203
B30: Facebook | C30: 0.0332 | G30: Facebook | H30: 319186 | I30: 2024 | J30: 11 | K30: 1 | L30: 540 | M30: 1.3989637 | W30: Facebook | X30: 45523 | Y30: =SUM([1]!Posts[[#This Row],[Likes]],[1]!Posts[[#This Row],[Shares]],[1]!Posts[[#This Row],[Comments]]) -> 3536 | Z30: =MONTH(X30) -> 8 | AA30: =INT((DAY(X30)-1)/7)+1 -> 3 | AB30: =YEAR(X30) -> 2024 | AC30: {=_xlfn.XLOOKUP(1, ('[1]Engagement Summary(Task1)'!$J$2:$J$201=Social_Media_Platform_Analysis!$AA30)*('[1]Engagement Summary(Task1)'!$I$2:$I$201=Social_Media_Platform_Analysis!$Z30)*('[1]Engagement Summary(Task1)'!$H$2:$H$201=Social_Media_Platform_Analysis!$AB30)*('[1]Engagement Summary(Task1)'!$B$2:$B$201=Social_Media_Platform_Analysis!$W30),'[1]Engagement Summary(Task1)'!$G$2:$G$201)} -> 14203 | AM30: Opinion on to focus 1-2 core platforms or multiplatforms
B31: Facebook | C31: 0.087 | G31: Facebook | H31: 309483 | I31: 2024 | J31: 11 | K31: 2 | L31: -106 | M31: -0.1962963 | W31: Facebook | X31: 45525 | Y31: =SUM([1]!Posts[[#This Row],[Likes]],[1]!Posts[[#This Row],[Shares]],[1]!Posts[[#This Row],[Comments]]) -> 3780 | Z31: =MONTH(X31) -> 8 | AA31: =INT((DAY(X31)-1)/7)+1 -> 3 | AB31: =YEAR(X31) -> 2024 | AC31: {=_xlfn.XLOOKUP(1, ('[1]Engagement Summary(Task1)'!$J$2:$J$201=Social_Media_Platform_Analysis!$AA31)*('[1]Engagement Summary(Task1)'!$I$2:$I$201=Social_Media_Platform_Analysis!$Z31)*('[1]Engagement Summary(Task1)'!$H$2:$H$201=Social_Media_Platform_Analysis!$AB31)*('[1]Engagement Summary(Task1)'!$B$2:$B$201=Social_Media_Platform_Analysis!$W31),'[1]Engagement Summary(Task1)'!$G$2:$G$201)} -> 14203 | AM31: As you see in this bar graph,there is not much difference in the engagement(likes+ shares+Comments) of different platforms .Even though there is engagement drop in 2025, but there is not much difference on engagements produced by different platforms. So,multi-platform strategy should be maintained to ensure audience reach and diversity, because each platform reaches a different segment of your audience, and no single platform is outperforming others enough to justify narrowing focus.
B32: Facebook | C32: 0.0268 | G32: Facebook | H32: 338847 | I32: 2024 | J32: 11 | K32: 3 | L32: 72 | M32: -0.67924528 | W32: Facebook | X32: 45528 | Y32: =SUM([1]!Posts[[#This Row],[Likes]],[1]!Posts[[#This Row],[Shares]],[1]!Posts[[#This Row],[Comments]]) -> 2375 | Z32: =MONTH(X32) -> 8 | AA32: =INT((DAY(X32)-1)/7)+1 -> 4 | AB32: =YEAR(X32) -> 2024 | AC32: {=_xlfn.XLOOKUP(1, ('[1]Engagement Summary(Task1)'!$J$2:$J$201=Social_Media_Platform_Analysis!$AA32)*('[1]Engagement Summary(Task1)'!$I$2:$I$201=Social_Media_Platform_Analysis!$Z32)*('[1]Engagement Summary(Task1)'!$H$2:$H$201=Social_Media_Platform_Analysis!$AB32)*('[1]Engagement Summary(Task1)'!$B$2:$B$201=Social_Media_Platform_Analysis!$W32),'[1]Engagement Summary(Task1)'!$G$2:$G$201)} -> 26925
B33: Facebook | C33: 0.062 | G33: Facebook | H33: 336661 | I33: 2024 | J33: 11 | K33: 4 | L33: 1332 | M33: 18.5 | W33: Facebook | X33: 45530 | Y33: =SUM([1]!Posts[[#This Row],[Likes]],[1]!Posts[[#This Row],[Shares]],[1]!Posts[[#This Row],[Comments]]) -> 1179 | Z33: =MONTH(X33) -> 8 | AA33: =INT((DAY(X33)-1)/7)+1 -> 4 | AB33: =YEAR(X33) -> 2024 | AC33: {=_xlfn.XLOOKUP(1, ('[1]Engagement Summary(Task1)'!$J$2:$J$201=Social_Media_Platform_Analysis!$AA33)*('[1]Engagement Summary(Task1)'!$I$2:$I$201=Social_Media_Platform_Analysis!$Z33)*('[1]Engagement Summary(Task1)'!$H$2:$H$201=Social_Media_Platform_Analysis!$AB33)*('[1]Engagement Summary(Task1)'!$B$2:$B$201=Social_Media_Platform_Analysis!$W33),'[1]Engagement Summary(Task1)'!$G$2:$G$201)} -> 26925
B34: Facebook | C34: 0.0479 | G34: Facebook | H34: 470269 | I34: 2024 | J34: 12 | K34: 1 | L34: 1706 | M34: 1.2807808 | W34: Facebook | X34: 45530 | Y34: =SUM([1]!Posts[[#This Row],[Likes]],[1]!Posts[[#This Row],[Shares]],[1]!Posts[[#This Row],[Comments]]) -> 2721 | Z34: =MONTH(X34) -> 8 | AA34: =INT((DAY(X34)-1)/7)+1 -> 4 | AB34: =YEAR(X34) -> 2024 | AC34: {=_xlfn.XLOOKUP(1, ('[1]Engagement Summary(Task1)'!$J$2:$J$201=Social_Media_Platform_Analysis!$AA34)*('[1]Engagement Summary(Task1)'!$I$2:$I$201=Social_Media_Platform_Analysis!$Z34)*('[1]Engagement Summary(Task1)'!$H$2:$H$201=Social_Media_Platform_Analysis!$AB34)*('[1]Engagement Summary(Task1)'!$B$2:$B$201=Social_Media_Platform_Analysis!$W34),'[1]Engagement Summary(Task1)'!$G$2:$G$201)} -> 26925
B35: Facebook | C35: 0.0747 | G35: Facebook | H35: 35842 | I35: 2024 | J35: 12 | K35: 2 | L35: 1373 | M35: 0.80480657 | W35: Facebook | X35: 45531 | Y35: =SUM([1]!Posts[[#This Row],[Likes]],[1]!Posts[[#This Row],[Shares]],[1]!Posts[[#This Row],[Comments]]) -> 3212 | Z35: =MONTH(X35) -> 8 | AA35: =INT((DAY(X35)-1)/7)+1 -> 4 | AB35: =YEAR(X35) -> 2024 | AC35: {=_xlfn.XLOOKUP(1, ('[1]Engagement Summary(Task1)'!$J$2:$J$201=Social_Media_Platform_Analysis!$AA35)*('[1]Engagement Summary(Task1)'!$I$2:$I$201=Social_Media_Platform_Analysis!$Z35)*('[1]Engagement Summary(Task1)'!$H$2:$H$201=Social_Media_Platform_Analysis!$AB35)*('[1]Engagement Summary(Task1)'!$B$2:$B$201=Social_Media_Platform_Analysis!$W35),'[1]Engagement Summary(Task1)'!$G$2:$G$201)} -> 26925
B36: Facebook | C36: 0.0811 | G36: Facebook | H36: 415815 | I36: 2024 | J36: 12 | K36: 3 | L36: 1377 | M36: 1.0029133 | W36: Facebook | X36: 45531 | Y36: =SUM([1]!Posts[[#This Row],[Likes]],[1]!Posts[[#This Row],[Shares]],[1]!Posts[[#This Row],[Comments]]) -> 866 | Z36: =MONTH(X36) -> 8 | AA36: =INT((DAY(X36)-1)/7)+1 -> 4 | AB36: =YEAR(X36) -> 2024 | AC36: {=_xlfn.XLOOKUP(1, ('[1]Engagement Summary(Task1)'!$J$2:$J$201=Social_Media_Platform_Analysis!$AA36)*('[1]Engagement Summary(Task1)'!$I$2:$I$201=Social_Media_Platform_Analysis!$Z36)*('[1]Engagement Summary(Task1)'!$H$2:$H$201=Social_Media_Platform_Analysis!$AB36)*('[1]Engagement Summary(Task1)'!$B$2:$B$201=Social_Media_Platform_Analysis!$W36),'[1]Engagement Summary(Task1)'!$G$2:$G$201)} -> 26925
B37: Facebook | C37: 0.0202 | G37: Facebook | H37: 93347 | I37: 2024 | J37: 12 | K37: 4 | L37: 730 | M37: 0.53013798 | W37: Facebook | X37: 45531 | Y37: =SUM([1]!Posts[[#This Row],[Likes]],[1]!Posts[[#This Row],[Shares]],[1]!Posts[[#This Row],[Comments]]) -> 2609 | Z37: =MONTH(X37) -> 8 | AA37: =INT((DAY(X37)-1)/7)+1 -> 4 | AB37: =YEAR(X37) -> 2024 | AC37: {=_xlfn.XLOOKUP(1, ('[1]Engagement Summary(Task1)'!$J$2:$J$201=Social_Media_Platform_Analysis!$AA37)*('[1]Engagement Summary(Task1)'!$I$2:$I$201=Social_Media_Platform_Analysis!$Z37)*('[1]Engagement Summary(Task1)'!$H$2:$H$201=Social_Media_Platform_Analysis!$AB37)*('[1]Engagement Summary(Task1)'!$B$2:$B$201=Social_Media_Platform_Analysis!$W37),'[1]Engagement Summary(Task1)'!$G$2:$G$201)} -> 26925
B38: Facebook | C38: 0.0309 | G38: Facebook | H38: 379431 | I38: 2024 | J38: 12 | K38: 5 | L38: 1776 | M38: 2.4328767 | W38: Facebook | X38: 45534 | Y38: =SUM([1]!Posts[[#This Row],[Likes]],[1]!Posts[[#This Row],[Shares]],[1]!Posts[[#This Row],[Comments]]) -> 2158 | Z38: =MONTH(X38) -> 8 | AA38: =INT((DAY(X38)-1)/7)+1 -> 5 | AB38: =YEAR(X38) -> 2024 | AC38: 0
B39: Facebook | C39: 0.082 | G39: Facebook | H39: 95728 | I39: 2025 | J39: 1 | K39: 1 | L39: 620 | M39: 0.3490991 | W39: Facebook | X39: 45573 | Y39: =SUM([1]!Posts[[#This Row],[Likes]],[1]!Posts[[#This Row],[Shares]],[1]!Posts[[#This Row],[Comments]]) -> 2098 | Z39: =MONTH(X39) -> 10 | AA39: =INT((DAY(X39)-1)/7)+1 -> 2 | AB39: =YEAR(X39) -> 2024 | AC39: {=_xlfn.XLOOKUP(1, ('[1]Engagement Summary(Task1)'!$J$2:$J$201=Social_Media_Platform_Analysis!$AA39)*('[1]Engagement Summary(Task1)'!$I$2:$I$201=Social_Media_Platform_Analysis!$Z39)*('[1]Engagement Summary(Task1)'!$H$2:$H$201=Social_Media_Platform_Analysis!$AB39)*('[1]Engagement Summary(Task1)'!$B$2:$B$201=Social_Media_Platform_Analysis!$W39),'[1]Engagement Summary(Task1)'!$G$2:$G$201)} -> 7285
B40: Facebook | C40: 0.0561 | G40: Facebook | H40: 224699 | I40: 2025 | J40: 1 | K40: 2 | L40: 298 | M40: 0.48064516 | W40: Facebook | X40: 45573 | Y40: =SUM([1]!Posts[[#This Row],[Likes]],[1]!Posts[[#This Row],[Shares]],[1]!Posts[[#This Row],[Comments]]) -> 4030 | Z40: =MONTH(X40) -> 10 | AA40: =INT((DAY(X40)-1)/7)+1 -> 2 | AB40: =YEAR(X40) -> 2024 | AC40: {=_xlfn.XLOOKUP(1, ('[1]Engagement Summary(Task1)'!$J$2:$J$201=Social_Media_Platform_Analysis!$AA40)*('[1]Engagement Summary(Task1)'!$I$2:$I$201=Social_Media_Platform_Analysis!$Z40)*('[1]Engagement Summary(Task1)'!$H$2:$H$201=Social_Media_Platform_Analysis!$AB40)*('[1]Engagement Summary(Task1)'!$B$2:$B$201=Social_Media_Platform_Analysis!$W40),'[1]Engagement Summary(Task1)'!$G$2:$G$201)} -> 7285
B41: Facebook | C41: 0.0451 | G41: Facebook | H41: 479490 | I41: 2025 | J41: 1 | K41: 3 | L41: 427 | M41: 1.4328859 | W41: Facebook | X41: 45576 | Y41: =SUM([1]!Posts[[#This Row],[Likes]],[1]!Posts[[#This Row],[Shares]],[1]!Posts[[#This Row],[Comments]]) -> 5186 | Z41: =MONTH(X41) -> 10 | AA41: =INT((DAY(X41)-1)/7)+1 -> 2 | AB41: =YEAR(X41) -> 2024 | AC41: {=_xlfn.XLOOKUP(1, ('[1]Engagement Summary(Task1)'!$J$2:$J$201=Social_Media_Platform_Analysis!$AA41)*('[1]Engagement Summary(Task1)'!$I$2:$I$201=Social_Media_Platform_Analysis!$Z41)*('[1]Engagement Summary(Task1)'!$H$2:$H$201=Social_Media_Platform_Analysis!$AB41)*('[1]Engagement Summary(Task1)'!$B$2:$B$201=Social_Media_Platform_Analysis!$W41),'[1]Engagement Summary(Task1)'!$G$2:$G$201)} -> 7285
B42: Facebook | C42: 0.0637 | G42: Facebook | H42: 321307 | I42: 2025 | J42: 1 | K42: 4 | L42: 898 | M42: 2.1030445 | W42: Facebook | X42: 45583 | Y42: =SUM([1]!Posts[[#This Row],[Likes]],[1]!Posts[[#This Row],[Shares]],[1]!Posts[[#This Row],[Comments]]) -> 4299 | Z42: =MONTH(X42) -> 10 | AA42: =INT((DAY(X42)-1)/7)+1 -> 3 | AB42: =YEAR(X42) -> 2024 | AC42: {=_xlfn.XLOOKUP(1, ('[1]Engagement Summary(Task1)'!$J$2:$J$201=Social_Media_Platform_Analysis!$AA42)*('[1]Engagement Summary(Task1)'!$I$2:$I$201=Social_Media_Platform_Analysis!$Z42)*('[1]Engagement Summary(Task1)'!$H$2:$H$201=Social_Media_Platform_Analysis!$AB42)*('[1]Engagement Summary(Task1)'!$B$2:$B$201=Social_Media_Platform_Analysis!$W42),'[1]Engagement Summary(Task1)'!$G$2:$G$201)} -> 42824
...
